INFO _internal.py:122  * Running on http://127.0.0.1:5000/ (Press CTRL+C to quit)
INFO _internal.py:122 127.0.0.1 - - [13/Jun/2019 17:02:49] "GET /api/v1.0/index HTTP/1.1" 404 -
ERROR users.py:8 err msg
WARNING users.py:9 warn msg
INFO _internal.py:122 127.0.0.1 - - [13/Jun/2019 17:02:49] "GET /api/v1.0/ HTTP/1.1" 200 -
INFO _internal.py:122 127.0.0.1 - - [13/Jun/2019 17:02:58] "GET /api/v1.0 HTTP/1.1" 308 -
ERROR users.py:8 err msg
WARNING users.py:9 warn msg
INFO _internal.py:122 127.0.0.1 - - [13/Jun/2019 17:02:58] "GET /api/v1.0/ HTTP/1.1" 200 -
INFO _internal.py:122 127.0.0.1 - - [13/Jun/2019 17:03:17] "GET /api/v1.0/image_code HTTP/1.1" 404 -
ERROR verify_code.py:30 Error 10061 connecting to 127.0.0.1:6379. 由于目标计算机积极拒绝，无法连接。.
INFO _internal.py:122 127.0.0.1 - - [13/Jun/2019 17:03:23] "GET /api/v1.0/image_code/33 HTTP/1.1" 200 -
INFO _internal.py:122  * Running on http://127.0.0.1:5000/ (Press CTRL+C to quit)
INFO _internal.py:122 127.0.0.1 - - [13/Jun/2019 18:05:32] "GET /api/v1.0/image_code/33 HTTP/1.1" 200 -
INFO _internal.py:122 127.0.0.1 - - [13/Jun/2019 18:05:48] "GET /api/v1.0/image_code/31 HTTP/1.1" 200 -
INFO _internal.py:122 127.0.0.1 - - [13/Jun/2019 18:05:54] "GET /api/v1.0/image_code/32 HTTP/1.1" 200 -
ERROR verify_code.py:30 Error 10061 connecting to 127.0.0.1:6379. 由于目标计算机积极拒绝，无法连接。.
INFO _internal.py:122 127.0.0.1 - - [13/Jun/2019 18:09:11] "GET /api/v1.0/image_code/32 HTTP/1.1" 200 -
INFO _internal.py:122 127.0.0.1 - - [13/Jun/2019 18:09:31] "GET /api/v1.0/image_code/32 HTTP/1.1" 200 -
ERROR verify_code.py:30 Error 10061 connecting to 127.0.0.1:6379. 由于目标计算机积极拒绝，无法连接。.
INFO _internal.py:122 127.0.0.1 - - [13/Jun/2019 18:16:53] "GET /api/v1.0/image_code/32 HTTP/1.1" 200 -
ERROR verify_code.py:30 Error 10061 connecting to 127.0.0.1:6379. 由于目标计算机积极拒绝，无法连接。.
INFO _internal.py:122 127.0.0.1 - - [13/Jun/2019 18:16:57] "GET /api/v1.0/image_code/32 HTTP/1.1" 200 -
ERROR verify_code.py:30 Error 10061 connecting to 127.0.0.1:6379. 由于目标计算机积极拒绝，无法连接。.
INFO _internal.py:122 127.0.0.1 - - [13/Jun/2019 18:17:02] "GET /api/v1.0/image_code/34 HTTP/1.1" 200 -
INFO _internal.py:122  * Running on http://127.0.0.1:5000/ (Press CTRL+C to quit)
ERROR verify_code.py:30 Error 10061 connecting to 127.0.0.1:6379. 由于目标计算机积极拒绝，无法连接。.
INFO _internal.py:122 127.0.0.1 - - [13/Jun/2019 18:23:41] "GET /api/v1.0/image_code/34 HTTP/1.1" 200 -
INFO _internal.py:122  * Running on http://127.0.0.1:5000/ (Press CTRL+C to quit)
ERROR verify_code.py:30 Error 10061 connecting to 127.0.0.1:6379. 由于目标计算机积极拒绝，无法连接。.
INFO _internal.py:122 127.0.0.1 - - [13/Jun/2019 18:26:48] "GET /api/v1.0/image_code/34 HTTP/1.1" 200 -
ERROR verify_code.py:30 Error 10061 connecting to 127.0.0.1:6379. 由于目标计算机积极拒绝，无法连接。.
INFO _internal.py:122 127.0.0.1 - - [13/Jun/2019 18:26:49] "GET /api/v1.0/image_code/34 HTTP/1.1" 200 -
INFO _internal.py:122  * Running on http://127.0.0.1:5000/ (Press CTRL+C to quit)
ERROR verify_code.py:30 Error 10061 connecting to 127.0.0.1:6379. 由于目标计算机积极拒绝，无法连接。.
INFO _internal.py:122 127.0.0.1 - - [13/Jun/2019 18:30:25] "GET /api/v1.0/image_code/34 HTTP/1.1" 200 -
ERROR verify_code.py:30 Error 10061 connecting to 127.0.0.1:6379. 由于目标计算机积极拒绝，无法连接。.
INFO _internal.py:122 127.0.0.1 - - [13/Jun/2019 18:30:36] "GET /api/v1.0/image_code/34 HTTP/1.1" 200 -
ERROR verify_code.py:30 Error 10061 connecting to 127.0.0.1:6379. 由于目标计算机积极拒绝，无法连接。.
INFO _internal.py:122 127.0.0.1 - - [13/Jun/2019 18:31:02] "GET /api/v1.0/image_code/34 HTTP/1.1" 200 -
INFO _internal.py:122 127.0.0.1 - - [13/Jun/2019 18:35:12] "GET /api/v1.0/image_code/34 HTTP/1.1" 200 -
INFO _internal.py:122  * Running on http://127.0.0.1:5000/ (Press CTRL+C to quit)
INFO _internal.py:122 127.0.0.1 - - [14/Jun/2019 10:24:03] "GET /api/v1.0/image_code/34 HTTP/1.1" 200 -
INFO _internal.py:122 127.0.0.1 - - [14/Jun/2019 10:24:03] "GET /favicon.ico HTTP/1.1" 404 -
INFO _internal.py:122  * Running on http://127.0.0.1:5000/ (Press CTRL+C to quit)
INFO _internal.py:122 127.0.0.1 - - [14/Jun/2019 10:51:16] "GET /api/v1.0/image_code/22 HTTP/1.1" 200 -
INFO _internal.py:122  * Running on http://127.0.0.1:5000/ (Press CTRL+C to quit)
INFO _internal.py:122 127.0.0.1 - - [14/Jun/2019 10:53:41] "GET /api/v1.0/image_code/22 HTTP/1.1" 200 -
INFO _internal.py:122 127.0.0.1 - - [14/Jun/2019 10:53:44] "GET /api/v1.0/image_code/23 HTTP/1.1" 200 -
INFO _internal.py:122  * Running on http://127.0.0.1:5000/ (Press CTRL+C to quit)
INFO _internal.py:122 127.0.0.1 - - [17/Jun/2019 10:22:01] "GET / HTTP/1.1" 304 -
ERROR verify_code.py:26 Error 10061 connecting to 127.0.0.1:6379. 由于目标计算机积极拒绝，无法连接。.
INFO _internal.py:122 127.0.0.1 - - [17/Jun/2019 10:22:10] "GET /api/v1.0/image_code/33 HTTP/1.1" 200 -
INFO _internal.py:122 127.0.0.1 - - [17/Jun/2019 10:22:10] "GET /favicon.ico HTTP/1.1" 404 -
INFO _internal.py:122 127.0.0.1 - - [17/Jun/2019 10:22:10] "GET /favicon.ico HTTP/1.1" 404 -
INFO _internal.py:122 127.0.0.1 - - [17/Jun/2019 10:22:41] "GET /api/v1.0/image_code/33 HTTP/1.1" 200 -
INFO _internal.py:122 127.0.0.1 - - [17/Jun/2019 10:28:17] "GET /api/v1.0/image_code/33 HTTP/1.1" 200 -
INFO _internal.py:122 127.0.0.1 - - [17/Jun/2019 10:30:35] "GET /api/v1.0/get_sms_code HTTP/1.1" 404 -
INFO _internal.py:122 127.0.0.1 - - [17/Jun/2019 10:31:20] "GET /api/v1.0/get_sms_code HTTP/1.1" 404 -
INFO _internal.py:122 127.0.0.1 - - [17/Jun/2019 10:31:32] "GET /api/v1.0/get_sms_code HTTP/1.1" 404 -
INFO _internal.py:122 127.0.0.1 - - [17/Jun/2019 10:31:48] "GET /api/v1.0/sms_code HTTP/1.1" 404 -
INFO _internal.py:122 127.0.0.1 - - [17/Jun/2019 10:32:20] "GET /api/v1.0/sms_code/17603094608 HTTP/1.1" 200 -
INFO _internal.py:122 127.0.0.1 - - [17/Jun/2019 10:32:40] "GET /api/v1.0/get_sms_code/17603094608 HTTP/1.1" 404 -
INFO _internal.py:122 127.0.0.1 - - [17/Jun/2019 10:32:43] "GET /api/v1.0/get_sms_code/17603094608 HTTP/1.1" 404 -
INFO _internal.py:122 127.0.0.1 - - [17/Jun/2019 10:32:48] "GET /api/v1.0/get_sms_code/17603094608 HTTP/1.1" 404 -
INFO _internal.py:122 127.0.0.1 - - [17/Jun/2019 10:32:59] "GET /api/v1.0/sms_code/17603094608 HTTP/1.1" 200 -
INFO _internal.py:122 127.0.0.1 - - [17/Jun/2019 10:33:55] "GET /api/v1.0/sms_code HTTP/1.1" 404 -
INFO _internal.py:122 127.0.0.1 - - [17/Jun/2019 10:34:26] "GET /api/v1.0/image_code/33 HTTP/1.1" 200 -
INFO _internal.py:122 127.0.0.1 - - [17/Jun/2019 10:35:26] "GET /api/v1.0/sms_code/17603094068 HTTP/1.1" 200 -
INFO _internal.py:122 127.0.0.1 - - [17/Jun/2019 10:35:35] "GET /api/v1.0/sms_code/17603094068 HTTP/1.1" 200 -
INFO _internal.py:122 127.0.0.1 - - [17/Jun/2019 10:36:42] "GET /api/v1.0/sms_code/17603094068 HTTP/1.1" 200 -
INFO _internal.py:122  * Running on http://127.0.0.1:5000/ (Press CTRL+C to quit)
INFO _internal.py:122 127.0.0.1 - - [17/Jun/2019 10:37:04] "GET /api/v1.0/sms_code/17603094068 HTTP/1.1" 200 -
INFO _internal.py:122  * Running on http://127.0.0.1:5000/ (Press CTRL+C to quit)
INFO _internal.py:122 127.0.0.1 - - [17/Jun/2019 10:37:30] "GET /api/v1.0/sms_code/17603094068 HTTP/1.1" 200 -
INFO _internal.py:122 127.0.0.1 - - [17/Jun/2019 10:43:46] "GET /api/v1.0/sms_code/17603094068 HTTP/1.1" 200 -
INFO _internal.py:122  * Running on http://127.0.0.1:5000/ (Press CTRL+C to quit)
INFO _internal.py:122 127.0.0.1 - - [17/Jun/2019 10:44:25] "GET /api/v1.0/sms_code/17603094068 HTTP/1.1" 200 -
INFO _internal.py:122 127.0.0.1 - - [17/Jun/2019 10:44:44] "GET /api/v1.0/sms_code/17603094608 HTTP/1.1" 200 -
INFO _internal.py:122 127.0.0.1 - - [17/Jun/2019 10:44:47] "GET /api/v1.0/sms_code/17603094608 HTTP/1.1" 200 -
INFO _internal.py:122 127.0.0.1 - - [17/Jun/2019 10:44:54] "GET /api/v1.0/sms_code/17603094608 HTTP/1.1" 200 -
INFO _internal.py:122  * Running on http://127.0.0.1:5000/ (Press CTRL+C to quit)
INFO _internal.py:122 127.0.0.1 - - [17/Jun/2019 10:46:54] "GET /api/v1.0/sms_code/17603094068 HTTP/1.1" 200 -
INFO _internal.py:122  * Running on http://127.0.0.1:5000/ (Press CTRL+C to quit)
INFO _internal.py:122 127.0.0.1 - - [17/Jun/2019 10:47:31] "GET /api/v1.0/sms_code/17603094068 HTTP/1.1" 200 -
INFO _internal.py:122 127.0.0.1 - - [17/Jun/2019 10:48:15] "GET /api/v1.0/sms_code/17603094068?image_code=VBAE&image_code_id=image_code_33 HTTP/1.1" 200 -
INFO _internal.py:122 127.0.0.1 - - [17/Jun/2019 10:48:36] "GET /api/v1.0/image_code/33 HTTP/1.1" 200 -
INFO _internal.py:122 127.0.0.1 - - [17/Jun/2019 10:49:01] "GET /api/v1.0/sms_code/17603094068?image_code=RZIY&image_code_id=image_code_33 HTTP/1.1" 200 -
INFO _internal.py:122 127.0.0.1 - - [17/Jun/2019 10:49:51] "GET /api/v1.0/sms_code/17603094068?image_code=RZIY&image_code_id=image_code_33 HTTP/1.1" 200 -
INFO _internal.py:122 127.0.0.1 - - [17/Jun/2019 10:50:58] "GET /api/v1.0/sms_code/17603094068?image_code=RZIY&image_code_id=33 HTTP/1.1" 200 -
INFO _internal.py:122 127.0.0.1 - - [17/Jun/2019 10:51:17] "GET /api/v1.0/image_code/33 HTTP/1.1" 200 -
INFO _internal.py:122 127.0.0.1 - - [17/Jun/2019 10:51:37] "GET /api/v1.0/sms_code/17603094068?image_code=SDVZ&image_code_id=33 HTTP/1.1" 200 -
INFO _internal.py:122  * Running on http://127.0.0.1:5000/ (Press CTRL+C to quit)
INFO _internal.py:122 127.0.0.1 - - [17/Jun/2019 10:52:30] "GET /api/v1.0/sms_code/17603094068?image_code=SDVZ&image_code_id=33 HTTP/1.1" 200 -
INFO _internal.py:122 127.0.0.1 - - [17/Jun/2019 10:52:46] "GET /api/v1.0/image_code/33 HTTP/1.1" 200 -
INFO _internal.py:122 127.0.0.1 - - [17/Jun/2019 10:52:46] "GET /api/v1.0/image_code/33 HTTP/1.1" 200 -
INFO _internal.py:122 127.0.0.1 - - [17/Jun/2019 10:53:11] "GET /api/v1.0/sms_code/17603094068?image_code=DGNC&image_code_id=33 HTTP/1.1" 200 -
INFO _internal.py:122  * Running on http://127.0.0.1:5000/ (Press CTRL+C to quit)
INFO _internal.py:122 127.0.0.1 - - [17/Jun/2019 10:54:43] "GET /api/v1.0/image_code/33 HTTP/1.1" 200 -
INFO _internal.py:122 127.0.0.1 - - [17/Jun/2019 10:55:03] "GET /api/v1.0/sms_code/17603094068?image_code=T6VR&image_code_id=33 HTTP/1.1" 200 -
INFO _internal.py:122 127.0.0.1 - - [17/Jun/2019 11:08:04] "GET /api/v1.0/sms_code/17603094068?image_code=T6VR&image_code_id=33 HTTP/1.1" 200 -
INFO _internal.py:122 127.0.0.1 - - [17/Jun/2019 11:08:13] "GET /api/v1.0/image_code/33 HTTP/1.1" 200 -
INFO _internal.py:122 127.0.0.1 - - [17/Jun/2019 11:08:59] "GET /api/v1.0/sms_code/17603094068?image_code_id=33&image_code=PZDN HTTP/1.1" 200 -
INFO _internal.py:122  * Running on http://127.0.0.1:5000/ (Press CTRL+C to quit)
ERROR verify_code.py:45 'NoneType' object has no attribute 'decode'
INFO _internal.py:122 127.0.0.1 - - [17/Jun/2019 11:09:18] "GET /api/v1.0/sms_code/17603094068?image_code_id=33&image_code=PZDN HTTP/1.1" 200 -
INFO _internal.py:122  * Running on http://127.0.0.1:5000/ (Press CTRL+C to quit)
INFO _internal.py:122 127.0.0.1 - - [17/Jun/2019 11:11:18] "GET /api/v1.0/sms_code/17603094068?image_code_id=33&image_code=PZDN HTTP/1.1" 200 -
INFO _internal.py:122 127.0.0.1 - - [17/Jun/2019 11:11:31] "GET /api/v1.0/image_code/33 HTTP/1.1" 200 -
ERROR app.py:1780 Exception on /api/v1.0/sms_code/17603094068 [GET]
Traceback (most recent call last):
  File "D:\Python\lib\site-packages\flask\app.py", line 2311, in wsgi_app
    response = self.full_dispatch_request()
  File "D:\Python\lib\site-packages\flask\app.py", line 1834, in full_dispatch_request
    rv = self.handle_user_exception(e)
  File "D:\Python\lib\site-packages\flask\app.py", line 1737, in handle_user_exception
    reraise(exc_type, exc_value, tb)
  File "D:\Python\lib\site-packages\flask\_compat.py", line 36, in reraise
    raise value
  File "D:\Python\lib\site-packages\flask\app.py", line 1832, in full_dispatch_request
    rv = self.dispatch_request()
  File "D:\Python\lib\site-packages\flask\app.py", line 1818, in dispatch_request
    return self.view_functions[rule.endpoint](**req.view_args)
  File "D:\python_demo\python\09ihome\ihome\api_1_0\verify_code.py", line 81, in get_sms_code
    sms_code = "%06d" % random(0, 999999)
TypeError: 'module' object is not callable
INFO _internal.py:122 127.0.0.1 - - [17/Jun/2019 11:11:53] "GET /api/v1.0/sms_code/17603094068?image_code_id=33&image_code=HL4P HTTP/1.1" 500 -
INFO _internal.py:122  * Running on http://127.0.0.1:5000/ (Press CTRL+C to quit)
INFO _internal.py:122 127.0.0.1 - - [17/Jun/2019 11:13:05] "GET /api/v1.0/sms_code/17603094068?image_code_id=33&image_code=HL4P HTTP/1.1" 200 -
INFO _internal.py:122 127.0.0.1 - - [17/Jun/2019 11:13:29] "GET /api/v1.0/image_code/33 HTTP/1.1" 200 -
INFO _internal.py:122 127.0.0.1 - - [17/Jun/2019 11:13:52] "GET /api/v1.0/sms_code/17603094068?image_code_id=33&image_code=OTPN HTTP/1.1" 200 -
INFO _internal.py:122  * Running on http://127.0.0.1:5000/ (Press CTRL+C to quit)
INFO _internal.py:122 127.0.0.1 - - [17/Jun/2019 11:15:36] "GET /api/v1.0/image_code/33 HTTP/1.1" 200 -
INFO _internal.py:122 127.0.0.1 - - [17/Jun/2019 11:15:36] "GET /api/v1.0/image_code/33 HTTP/1.1" 200 -
ERROR app.py:1780 Exception on /api/v1.0/sms_code/17603094068 [GET]
Traceback (most recent call last):
  File "D:\Python\lib\site-packages\flask\app.py", line 2311, in wsgi_app
    response = self.full_dispatch_request()
  File "D:\Python\lib\site-packages\flask\app.py", line 1834, in full_dispatch_request
    rv = self.handle_user_exception(e)
  File "D:\Python\lib\site-packages\flask\app.py", line 1737, in handle_user_exception
    reraise(exc_type, exc_value, tb)
  File "D:\Python\lib\site-packages\flask\_compat.py", line 36, in reraise
    raise value
  File "D:\Python\lib\site-packages\flask\app.py", line 1832, in full_dispatch_request
    rv = self.dispatch_request()
  File "D:\Python\lib\site-packages\flask\app.py", line 1818, in dispatch_request
    return self.view_functions[rule.endpoint](**req.view_args)
  File "D:\python_demo\python\09ihome\ihome\api_1_0\verify_code.py", line 80, in get_sms_code
    sms_code = "%06d" % random(0, 999999)
TypeError: 'module' object is not callable
INFO _internal.py:122 127.0.0.1 - - [17/Jun/2019 11:15:58] "GET /api/v1.0/sms_code/17603094068?image_code_id=33&image_code=UQOL HTTP/1.1" 500 -
INFO _internal.py:122  * Running on http://127.0.0.1:5000/ (Press CTRL+C to quit)
INFO _internal.py:122 127.0.0.1 - - [17/Jun/2019 11:19:05] "GET /api/v1.0/image_code/33 HTTP/1.1" 200 -
ERROR app.py:1780 Exception on /api/v1.0/sms_code/17603094068 [GET]
Traceback (most recent call last):
  File "D:\Python\lib\site-packages\flask\app.py", line 2311, in wsgi_app
    response = self.full_dispatch_request()
  File "D:\Python\lib\site-packages\flask\app.py", line 1834, in full_dispatch_request
    rv = self.handle_user_exception(e)
  File "D:\Python\lib\site-packages\flask\app.py", line 1737, in handle_user_exception
    reraise(exc_type, exc_value, tb)
  File "D:\Python\lib\site-packages\flask\_compat.py", line 36, in reraise
    raise value
  File "D:\Python\lib\site-packages\flask\app.py", line 1832, in full_dispatch_request
    rv = self.dispatch_request()
  File "D:\Python\lib\site-packages\flask\app.py", line 1818, in dispatch_request
    return self.view_functions[rule.endpoint](**req.view_args)
  File "D:\python_demo\python\09ihome\ihome\api_1_0\verify_code.py", line 94, in get_sms_code
    result = client.send('17603094608', '您的验证码为%d' % sms_code)
TypeError: %d format: a number is required, not str
INFO _internal.py:122 127.0.0.1 - - [17/Jun/2019 11:19:28] "GET /api/v1.0/sms_code/17603094068?image_code_id=33&image_code=A7PY HTTP/1.1" 500 -
INFO _internal.py:122  * Running on http://127.0.0.1:5000/ (Press CTRL+C to quit)
INFO _internal.py:122 127.0.0.1 - - [17/Jun/2019 11:21:09] "GET /api/v1.0/image_code/33 HTTP/1.1" 200 -
ERROR app.py:1780 Exception on /api/v1.0/sms_code/17603094068 [GET]
Traceback (most recent call last):
  File "D:\Python\lib\site-packages\flask\app.py", line 2311, in wsgi_app
    response = self.full_dispatch_request()
  File "D:\Python\lib\site-packages\flask\app.py", line 1834, in full_dispatch_request
    rv = self.handle_user_exception(e)
  File "D:\Python\lib\site-packages\flask\app.py", line 1737, in handle_user_exception
    reraise(exc_type, exc_value, tb)
  File "D:\Python\lib\site-packages\flask\_compat.py", line 36, in reraise
    raise value
  File "D:\Python\lib\site-packages\flask\app.py", line 1832, in full_dispatch_request
    rv = self.dispatch_request()
  File "D:\Python\lib\site-packages\flask\app.py", line 1818, in dispatch_request
    return self.view_functions[rule.endpoint](**req.view_args)
  File "D:\python_demo\python\09ihome\ihome\api_1_0\verify_code.py", line 95, in get_sms_code
    result = client.send('17603094608', '您的验证码为%d' % sms_code)
TypeError: %d format: a number is required, not str
INFO _internal.py:122 127.0.0.1 - - [17/Jun/2019 11:21:34] "GET /api/v1.0/sms_code/17603094068?image_code_id=33&image_code=VUWQ HTTP/1.1" 500 -
INFO _internal.py:122  * Running on http://127.0.0.1:5000/ (Press CTRL+C to quit)
INFO _internal.py:122 127.0.0.1 - - [17/Jun/2019 11:22:27] "GET /api/v1.0/sms_code/17603094068?image_code_id=33&image_code=VUWQ HTTP/1.1" 200 -
INFO _internal.py:122 127.0.0.1 - - [17/Jun/2019 11:22:42] "GET /api/v1.0/sms_code/17603094068?image_code_id=33&image_code=VUWQ HTTP/1.1" 200 -
INFO _internal.py:122 127.0.0.1 - - [17/Jun/2019 11:22:44] "GET /api/v1.0/sms_code/17603094068?image_code_id=33&image_code=VUWQ HTTP/1.1" 200 -
INFO _internal.py:122 127.0.0.1 - - [17/Jun/2019 11:22:45] "GET /api/v1.0/sms_code/17603094068?image_code_id=33&image_code=VUWQ HTTP/1.1" 200 -
INFO _internal.py:122 127.0.0.1 - - [17/Jun/2019 11:22:45] "GET /api/v1.0/sms_code/17603094068?image_code_id=33&image_code=VUWQ HTTP/1.1" 200 -
INFO _internal.py:122 127.0.0.1 - - [17/Jun/2019 11:22:46] "GET /api/v1.0/sms_code/17603094068?image_code_id=33&image_code=VUWQ HTTP/1.1" 200 -
INFO _internal.py:122 127.0.0.1 - - [17/Jun/2019 11:22:47] "GET /api/v1.0/sms_code/17603094068?image_code_id=33&image_code=VUWQ HTTP/1.1" 200 -
INFO _internal.py:122 127.0.0.1 - - [17/Jun/2019 11:22:48] "GET /api/v1.0/sms_code/17603094068?image_code_id=33&image_code=VUWQ HTTP/1.1" 200 -
INFO _internal.py:122 127.0.0.1 - - [17/Jun/2019 11:22:49] "GET /api/v1.0/sms_code/17603094068?image_code_id=33&image_code=VUWQ HTTP/1.1" 200 -
INFO _internal.py:122 127.0.0.1 - - [17/Jun/2019 11:22:50] "GET /api/v1.0/sms_code/17603094068?image_code_id=33&image_code=VUWQ HTTP/1.1" 200 -
INFO _internal.py:122 127.0.0.1 - - [17/Jun/2019 11:22:50] "GET /api/v1.0/sms_code/17603094068?image_code_id=33&image_code=VUWQ HTTP/1.1" 200 -
INFO _internal.py:122 127.0.0.1 - - [17/Jun/2019 11:22:51] "GET /api/v1.0/sms_code/17603094068?image_code_id=33&image_code=VUWQ HTTP/1.1" 200 -
INFO _internal.py:122 127.0.0.1 - - [17/Jun/2019 11:22:52] "GET /api/v1.0/sms_code/17603094068?image_code_id=33&image_code=VUWQ HTTP/1.1" 200 -
INFO _internal.py:122 127.0.0.1 - - [17/Jun/2019 11:22:53] "GET /api/v1.0/sms_code/17603094068?image_code_id=33&image_code=VUWQ HTTP/1.1" 200 -
INFO _internal.py:122 127.0.0.1 - - [17/Jun/2019 11:22:53] "GET /api/v1.0/sms_code/17603094068?image_code_id=33&image_code=VUWQ HTTP/1.1" 200 -
INFO _internal.py:122 127.0.0.1 - - [17/Jun/2019 11:22:54] "GET /api/v1.0/sms_code/17603094068?image_code_id=33&image_code=VUWQ HTTP/1.1" 200 -
INFO _internal.py:122 127.0.0.1 - - [17/Jun/2019 11:22:54] "GET /api/v1.0/sms_code/17603094068?image_code_id=33&image_code=VUWQ HTTP/1.1" 200 -
INFO _internal.py:122 127.0.0.1 - - [17/Jun/2019 11:22:55] "GET /api/v1.0/sms_code/17603094068?image_code_id=33&image_code=VUWQ HTTP/1.1" 200 -
INFO _internal.py:122 127.0.0.1 - - [17/Jun/2019 11:22:55] "GET /api/v1.0/sms_code/17603094068?image_code_id=33&image_code=VUWQ HTTP/1.1" 200 -
INFO _internal.py:122 127.0.0.1 - - [17/Jun/2019 11:22:56] "GET /api/v1.0/sms_code/17603094068?image_code_id=33&image_code=VUWQ HTTP/1.1" 200 -
INFO _internal.py:122 127.0.0.1 - - [17/Jun/2019 11:22:57] "GET /api/v1.0/sms_code/17603094068?image_code_id=33&image_code=VUWQ HTTP/1.1" 200 -
INFO _internal.py:122 127.0.0.1 - - [17/Jun/2019 11:22:57] "GET /api/v1.0/sms_code/17603094068?image_code_id=33&image_code=VUWQ HTTP/1.1" 200 -
INFO _internal.py:122 127.0.0.1 - - [17/Jun/2019 11:22:58] "GET /api/v1.0/sms_code/17603094068?image_code_id=33&image_code=VUWQ HTTP/1.1" 200 -
INFO _internal.py:122 127.0.0.1 - - [17/Jun/2019 11:22:58] "GET /api/v1.0/sms_code/17603094068?image_code_id=33&image_code=VUWQ HTTP/1.1" 200 -
INFO _internal.py:122 127.0.0.1 - - [17/Jun/2019 11:22:59] "GET /api/v1.0/sms_code/17603094068?image_code_id=33&image_code=VUWQ HTTP/1.1" 200 -
INFO _internal.py:122  * Running on http://127.0.0.1:5000/ (Press CTRL+C to quit)
INFO _internal.py:122 127.0.0.1 - - [17/Jun/2019 11:23:39] "GET /api/v1.0/sms_code/17603094068?image_code_id=33&image_code=VUWQ HTTP/1.1" 200 -
INFO _internal.py:122 127.0.0.1 - - [17/Jun/2019 11:23:41] "GET /api/v1.0/sms_code/17603094068?image_code_id=33&image_code=VUWQ HTTP/1.1" 200 -
INFO _internal.py:122 127.0.0.1 - - [17/Jun/2019 11:23:43] "GET /api/v1.0/sms_code/17603094068?image_code_id=33&image_code=VUWQ HTTP/1.1" 200 -
INFO _internal.py:122 127.0.0.1 - - [17/Jun/2019 11:23:44] "GET /api/v1.0/sms_code/17603094068?image_code_id=33&image_code=VUWQ HTTP/1.1" 200 -
INFO _internal.py:122 127.0.0.1 - - [17/Jun/2019 11:23:45] "GET /api/v1.0/sms_code/17603094068?image_code_id=33&image_code=VUWQ HTTP/1.1" 200 -
INFO _internal.py:122 127.0.0.1 - - [17/Jun/2019 11:23:47] "GET /api/v1.0/sms_code/17603094068?image_code_id=33&image_code=VUWQ HTTP/1.1" 200 -
INFO _internal.py:122 127.0.0.1 - - [17/Jun/2019 11:23:47] "GET /api/v1.0/sms_code/17603094068?image_code_id=33&image_code=VUWQ HTTP/1.1" 200 -
INFO _internal.py:122 127.0.0.1 - - [17/Jun/2019 11:23:48] "GET /api/v1.0/sms_code/17603094068?image_code_id=33&image_code=VUWQ HTTP/1.1" 200 -
INFO _internal.py:122 127.0.0.1 - - [17/Jun/2019 11:23:49] "GET /api/v1.0/sms_code/17603094068?image_code_id=33&image_code=VUWQ HTTP/1.1" 200 -
INFO _internal.py:122  * Running on http://127.0.0.1:5000/ (Press CTRL+C to quit)
INFO _internal.py:122  * Running on http://127.0.0.1:5000/ (Press CTRL+C to quit)
INFO _internal.py:122 127.0.0.1 - - [17/Jun/2019 11:25:19] "GET /api/v1.0/image_code/33 HTTP/1.1" 200 -
ERROR verify_code.py:89 %d format: a number is required, not str
INFO _internal.py:122 127.0.0.1 - - [17/Jun/2019 11:25:46] "GET /api/v1.0/sms_code/17603094068?image_code_id=33&image_code=TLYA HTTP/1.1" 200 -
INFO _internal.py:122  * Running on http://127.0.0.1:5000/ (Press CTRL+C to quit)
INFO _internal.py:122 127.0.0.1 - - [17/Jun/2019 11:26:37] "GET /api/v1.0/sms_code/17603094068?image_code_id=33&image_code=TLYA HTTP/1.1" 200 -
INFO _internal.py:122 127.0.0.1 - - [17/Jun/2019 11:26:46] "GET /api/v1.0/image_code/33 HTTP/1.1" 200 -
INFO _internal.py:122 127.0.0.1 - - [17/Jun/2019 11:27:14] "GET /api/v1.0/sms_code/17603094068?image_code_id=33&image_code=XRBI HTTP/1.1" 200 -
INFO _internal.py:122 127.0.0.1 - - [17/Jun/2019 11:31:03] "GET /api/v1.0/image_code/33 HTTP/1.1" 200 -
INFO _internal.py:122 127.0.0.1 - - [17/Jun/2019 11:31:29] "GET /api/v1.0/sms_code/17603094068?image_code_id=33&image_code=N8G4 HTTP/1.1" 200 -
INFO _internal.py:122 127.0.0.1 - - [17/Jun/2019 14:55:07] "GET /api/v1.0/image_code/33 HTTP/1.1" 200 -
INFO _internal.py:122 127.0.0.1 - - [17/Jun/2019 14:55:07] "GET /api/v1.0/image_code/33 HTTP/1.1" 200 -
INFO _internal.py:122 127.0.0.1 - - [17/Jun/2019 14:55:33] "GET /api/v1.0/sms_code/17603094068?image_code_id=33&image_code=8PTQ HTTP/1.1" 200 -
INFO _internal.py:122 127.0.0.1 - - [17/Jun/2019 14:57:47] "GET /api/v1.0/users HTTP/1.1" 404 -
INFO _internal.py:122 127.0.0.1 - - [17/Jun/2019 14:57:55] "POST /api/v1.0/users HTTP/1.1" 405 -
INFO _internal.py:122 127.0.0.1 - - [17/Jun/2019 14:58:26] "POST /api/v1.0/users HTTP/1.1" 405 -
INFO _internal.py:122  * Running on http://127.0.0.1:5000/ (Press CTRL+C to quit)
INFO _internal.py:122  * Running on http://127.0.0.1:5000/ (Press CTRL+C to quit)
INFO _internal.py:122 127.0.0.1 - - [17/Jun/2019 15:01:33] "GET /api/v1.0/image_code/33 HTTP/1.1" 200 -
INFO _internal.py:122 127.0.0.1 - - [17/Jun/2019 15:02:02] "GET /api/v1.0/sms_code/17603094068?image_code_id=33&image_code=YEYU HTTP/1.1" 200 -
ERROR app.py:1780 Exception on /api/v1.0/users [POST]
Traceback (most recent call last):
  File "D:\Python\lib\site-packages\flask\app.py", line 2311, in wsgi_app
    response = self.full_dispatch_request()
  File "D:\Python\lib\site-packages\flask\app.py", line 1834, in full_dispatch_request
    rv = self.handle_user_exception(e)
  File "D:\Python\lib\site-packages\flask\app.py", line 1737, in handle_user_exception
    reraise(exc_type, exc_value, tb)
  File "D:\Python\lib\site-packages\flask\_compat.py", line 36, in reraise
    raise value
  File "D:\Python\lib\site-packages\flask\app.py", line 1832, in full_dispatch_request
    rv = self.dispatch_request()
  File "D:\Python\lib\site-packages\flask\app.py", line 1818, in dispatch_request
    return self.view_functions[rule.endpoint](**req.view_args)
  File "D:\python_demo\python\09ihome\ihome\api_1_0\passport.py", line 19, in register
    mobile = req_dict.get("mobile")
AttributeError: 'NoneType' object has no attribute 'get'
INFO _internal.py:122 127.0.0.1 - - [17/Jun/2019 15:02:23] "POST /api/v1.0/users HTTP/1.1" 500 -
ERROR app.py:1780 Exception on /api/v1.0/users [POST]
Traceback (most recent call last):
  File "D:\Python\lib\site-packages\flask\app.py", line 2311, in wsgi_app
    response = self.full_dispatch_request()
  File "D:\Python\lib\site-packages\flask\app.py", line 1834, in full_dispatch_request
    rv = self.handle_user_exception(e)
  File "D:\Python\lib\site-packages\flask\app.py", line 1737, in handle_user_exception
    reraise(exc_type, exc_value, tb)
  File "D:\Python\lib\site-packages\flask\_compat.py", line 36, in reraise
    raise value
  File "D:\Python\lib\site-packages\flask\app.py", line 1832, in full_dispatch_request
    rv = self.dispatch_request()
  File "D:\Python\lib\site-packages\flask\app.py", line 1818, in dispatch_request
    return self.view_functions[rule.endpoint](**req.view_args)
  File "D:\python_demo\python\09ihome\ihome\api_1_0\passport.py", line 19, in register
    mobile = req_dict.get("mobile")
AttributeError: 'NoneType' object has no attribute 'get'
INFO _internal.py:122 127.0.0.1 - - [17/Jun/2019 15:03:08] "POST /api/v1.0/users HTTP/1.1" 500 -
INFO _internal.py:122  * Running on http://127.0.0.1:5000/ (Press CTRL+C to quit)
ERROR app.py:1780 Exception on /api/v1.0/users [POST]
Traceback (most recent call last):
  File "D:\Python\lib\site-packages\flask\app.py", line 2311, in wsgi_app
    response = self.full_dispatch_request()
  File "D:\Python\lib\site-packages\flask\app.py", line 1834, in full_dispatch_request
    rv = self.handle_user_exception(e)
  File "D:\Python\lib\site-packages\flask\app.py", line 1737, in handle_user_exception
    reraise(exc_type, exc_value, tb)
  File "D:\Python\lib\site-packages\flask\_compat.py", line 36, in reraise
    raise value
  File "D:\Python\lib\site-packages\flask\app.py", line 1832, in full_dispatch_request
    rv = self.dispatch_request()
  File "D:\Python\lib\site-packages\flask\app.py", line 1818, in dispatch_request
    return self.view_functions[rule.endpoint](**req.view_args)
  File "D:\python_demo\python\09ihome\ihome\api_1_0\passport.py", line 20, in register
    mobile = req_dict.get("mobile")
AttributeError: 'NoneType' object has no attribute 'get'
INFO _internal.py:122 127.0.0.1 - - [17/Jun/2019 15:05:01] "POST /api/v1.0/users HTTP/1.1" 500 -
INFO _internal.py:122 127.0.0.1 - - [17/Jun/2019 15:05:37] "POST /api/v1.0/users HTTP/1.1" 400 -
INFO _internal.py:122  * Running on http://127.0.0.1:5000/ (Press CTRL+C to quit)
INFO _internal.py:122 127.0.0.1 - - [17/Jun/2019 15:06:15] "POST /api/v1.0/users HTTP/1.1" 400 -
INFO _internal.py:122 127.0.0.1 - - [17/Jun/2019 15:08:03] "POST /api/v1.0/users HTTP/1.1" 400 -
INFO _internal.py:122  * Running on http://127.0.0.1:5000/ (Press CTRL+C to quit)
INFO _internal.py:122 127.0.0.1 - - [17/Jun/2019 15:09:50] "POST /api/v1.0/users HTTP/1.1" 400 -
INFO _internal.py:122  * Running on http://127.0.0.1:5000/ (Press CTRL+C to quit)
INFO _internal.py:122 127.0.0.1 - - [17/Jun/2019 15:13:00] "POST /api/v1.0/users HTTP/1.1" 400 -
INFO _internal.py:122  * Running on http://127.0.0.1:5000/ (Press CTRL+C to quit)
INFO _internal.py:122 127.0.0.1 - - [17/Jun/2019 15:17:56] "POST /api/v1.0/users HTTP/1.1" 400 -
INFO _internal.py:122 127.0.0.1 - - [17/Jun/2019 15:27:30] "POST /api/v1.0/users HTTP/1.1" 400 -
INFO _internal.py:122 127.0.0.1 - - [17/Jun/2019 15:30:49] "POST /api/v1.0/users HTTP/1.1" 400 -
ERROR app.py:1780 Exception on /api/v1.0/users [POST]
Traceback (most recent call last):
  File "D:\Python\lib\site-packages\flask\app.py", line 2311, in wsgi_app
    response = self.full_dispatch_request()
  File "D:\Python\lib\site-packages\flask\app.py", line 1834, in full_dispatch_request
    rv = self.handle_user_exception(e)
  File "D:\Python\lib\site-packages\flask\app.py", line 1737, in handle_user_exception
    reraise(exc_type, exc_value, tb)
  File "D:\Python\lib\site-packages\flask\_compat.py", line 36, in reraise
    raise value
  File "D:\Python\lib\site-packages\flask\app.py", line 1832, in full_dispatch_request
    rv = self.dispatch_request()
  File "D:\Python\lib\site-packages\flask\app.py", line 1818, in dispatch_request
    return self.view_functions[rule.endpoint](**req.view_args)
  File "D:\python_demo\python\09ihome\ihome\api_1_0\passport.py", line 27, in register
    return jsonify(errno=RET.PARAMERR, errmsg="手机号格式错误")
  File "D:\Python\lib\re.py", line 173, in match
    return _compile(pattern, flags).match(string)
TypeError: expected string or bytes-like object
INFO _internal.py:122 127.0.0.1 - - [17/Jun/2019 15:34:26] "POST /api/v1.0/users HTTP/1.1" 500 -
INFO _internal.py:122  * Restarting with stat
WARNING _internal.py:122  * Debugger is active!
INFO _internal.py:122  * Debugger PIN: 603-595-559
INFO _internal.py:122  * Running on http://127.0.0.1:5000/ (Press CTRL+C to quit)
INFO _internal.py:122 127.0.0.1 - - [17/Jun/2019 15:41:08] "POST /api/v1.0/users HTTP/1.1" 500 -
INFO _internal.py:122  * Detected change in 'D:\\python_demo\\python\\09ihome\\ihome\\api_1_0\\passport.py', reloading
INFO _internal.py:122  * Restarting with stat
WARNING _internal.py:122  * Debugger is active!
INFO _internal.py:122  * Debugger PIN: 603-595-559
INFO _internal.py:122  * Running on http://127.0.0.1:5000/ (Press CTRL+C to quit)
INFO _internal.py:122  * Restarting with stat
WARNING _internal.py:122  * Debugger is active!
INFO _internal.py:122  * Debugger PIN: 603-595-559
INFO _internal.py:122  * Running on http://127.0.0.1:5000/ (Press CTRL+C to quit)
INFO _internal.py:122 127.0.0.1 - - [17/Jun/2019 15:42:44] "POST /api/v1.0/users HTTP/1.1" 500 -
INFO _internal.py:122  * Detected change in 'D:\\python_demo\\python\\09ihome\\ihome\\libs\\zhenzismsclient.py', reloading
INFO _internal.py:122  * Restarting with stat
WARNING _internal.py:122  * Debugger is active!
INFO _internal.py:122  * Debugger PIN: 603-595-559
INFO _internal.py:122  * Running on http://127.0.0.1:5000/ (Press CTRL+C to quit)
INFO _internal.py:122  * Detected change in 'D:\\python_demo\\python\\09ihome\\ihome\\libs\\zhenzismsclient.py', reloading
INFO _internal.py:122  * Restarting with stat
WARNING _internal.py:122  * Debugger is active!
INFO _internal.py:122  * Debugger PIN: 603-595-559
INFO _internal.py:122  * Running on http://127.0.0.1:5000/ (Press CTRL+C to quit)
INFO _internal.py:122  * Detected change in 'D:\\python_demo\\python\\09ihome\\ihome\\libs\\zhenzismsclient.py', reloading
INFO _internal.py:122  * Restarting with stat
INFO _internal.py:122  * Restarting with stat
WARNING _internal.py:122  * Debugger is active!
INFO _internal.py:122  * Debugger PIN: 603-595-559
INFO _internal.py:122  * Running on http://127.0.0.1:5000/ (Press CTRL+C to quit)
INFO _internal.py:122 127.0.0.1 - - [17/Jun/2019 15:52:17] "POST /api/v1.0/users HTTP/1.1" 200 -
INFO _internal.py:122 127.0.0.1 - - [17/Jun/2019 15:52:52] "GET /api/v1.0/image_code/33 HTTP/1.1" 200 -
INFO _internal.py:122 127.0.0.1 - - [17/Jun/2019 15:54:13] "GET /api/v1.0/sms_code/17603094068?image_code_id=33&image_code=XOCH HTTP/1.1" 200 -
INFO _internal.py:122 127.0.0.1 - - [17/Jun/2019 15:54:13] "GET /api/v1.0/sms_code/17603094068?image_code_id=33&image_code=XOCH HTTP/1.1" 200 -
INFO _internal.py:122 127.0.0.1 - - [17/Jun/2019 15:54:18] "GET /api/v1.0/image_code/33 HTTP/1.1" 200 -
INFO _internal.py:122 127.0.0.1 - - [17/Jun/2019 15:55:43] "GET /api/v1.0/sms_code/17603094068?image_code_id=33&image_code=SWUJ HTTP/1.1" 200 -
INFO _internal.py:122 127.0.0.1 - - [17/Jun/2019 15:55:43] "GET /api/v1.0/sms_code/17603094068?image_code_id=33&image_code=SWUJ HTTP/1.1" 200 -
INFO _internal.py:122 127.0.0.1 - - [17/Jun/2019 15:55:55] "GET /api/v1.0/sms_code/17603094068?image_code_id=33&image_code=SWUJ HTTP/1.1" 200 -
INFO _internal.py:122 127.0.0.1 - - [17/Jun/2019 15:56:22] "POST /api/v1.0/users HTTP/1.1" 400 -
INFO _internal.py:122 127.0.0.1 - - [17/Jun/2019 15:57:01] "POST /api/v1.0/users HTTP/1.1" 400 -
INFO _internal.py:122 127.0.0.1 - - [17/Jun/2019 15:57:48] "POST /api/v1.0/users HTTP/1.1" 400 -
INFO _internal.py:122 127.0.0.1 - - [17/Jun/2019 15:58:25] "POST /api/v1.0/users HTTP/1.1" 500 -
INFO _internal.py:122  * Restarting with stat
WARNING _internal.py:122  * Debugger is active!
INFO _internal.py:122  * Debugger PIN: 603-595-559
INFO _internal.py:122  * Running on http://127.0.0.1:5000/ (Press CTRL+C to quit)
INFO _internal.py:122 127.0.0.1 - - [19/Jun/2019 16:37:28] "GET / HTTP/1.1" 304 -
INFO _internal.py:122 127.0.0.1 - - [19/Jun/2019 16:37:41] "GET /favicon.ico HTTP/1.1" 404 -
ERROR verify_code.py:26 Error 10061 connecting to 127.0.0.1:6379. 由于目标计算机积极拒绝，无法连接。.
INFO _internal.py:122 127.0.0.1 - - [19/Jun/2019 16:37:42] "GET /api/v1.0/image_code/33 HTTP/1.1" 200 -
INFO _internal.py:122 127.0.0.1 - - [19/Jun/2019 16:38:28] "GET /api/v1.0/image_code/33 HTTP/1.1" 200 -
INFO _internal.py:122 127.0.0.1 - - [19/Jun/2019 16:40:36] "GET /api/v1.0/sms_code/17603094068?image_code_id=33&image_code=AAM7 HTTP/1.1" 200 -
INFO _internal.py:122 127.0.0.1 - - [19/Jun/2019 16:40:55] "POST /api/v1.0/users HTTP/1.1" 500 -
INFO _internal.py:122  * Detected change in 'D:\\python_demo\\python\\09ihome\\ihome\\api_1_0\\passport.py', reloading
INFO _internal.py:122  * Restarting with stat
WARNING _internal.py:122  * Debugger is active!
INFO _internal.py:122  * Debugger PIN: 603-595-559
INFO _internal.py:122  * Running on http://127.0.0.1:5000/ (Press CTRL+C to quit)
INFO _internal.py:122  * Restarting with stat
WARNING _internal.py:122  * Debugger is active!
INFO _internal.py:122  * Debugger PIN: 603-595-559
INFO _internal.py:122  * Running on http://127.0.0.1:5000/ (Press CTRL+C to quit)
INFO _internal.py:122  * Detected change in 'D:\\python_demo\\python\\09ihome\\ihome\\models.py', reloading
INFO _internal.py:122  * Restarting with stat
WARNING _internal.py:122  * Debugger is active!
INFO _internal.py:122  * Debugger PIN: 603-595-559
INFO _internal.py:122  * Running on http://127.0.0.1:5000/ (Press CTRL+C to quit)
INFO _internal.py:122 127.0.0.1 - - [19/Jun/2019 16:43:55] "POST /api/v1.0/users HTTP/1.1" 200 -
INFO _internal.py:122 127.0.0.1 - - [19/Jun/2019 16:44:05] "POST /api/v1.0/users HTTP/1.1" 200 -
INFO _internal.py:122 127.0.0.1 - - [19/Jun/2019 16:44:19] "GET /api/v1.0/sms_code/17603094068?image_code_id=33&image_code=AAM7 HTTP/1.1" 200 -
INFO _internal.py:122 127.0.0.1 - - [19/Jun/2019 16:44:41] "GET /api/v1.0/image_code/33 HTTP/1.1" 200 -
ERROR verify_code.py:74 (pymysql.err.InternalError) (1054, "Unknown column 'ih_user_profile.password' in 'field list'")
[SQL: SELECT ih_user_profile.create_time AS ih_user_profile_create_time, ih_user_profile.update_time AS ih_user_profile_update_time, ih_user_profile.id AS ih_user_profile_id, ih_user_profile.name AS ih_user_profile_name, ih_user_profile.password AS ih_user_profile_password, ih_user_profile.mobile AS ih_user_profile_mobile, ih_user_profile.real_name AS ih_user_profile_real_name, ih_user_profile.id_card AS ih_user_profile_id_card, ih_user_profile.avatar_url AS ih_user_profile_avatar_url 
FROM ih_user_profile 
WHERE ih_user_profile.mobile = %(mobile_1)s 
 LIMIT %(param_1)s]
[parameters: {'mobile_1': '17603094068', 'param_1': 1}]
(Background on this error at: http://sqlalche.me/e/2j85)
INFO _internal.py:122 127.0.0.1 - - [19/Jun/2019 16:44:55] "GET /api/v1.0/sms_code/17603094068?image_code_id=33&image_code=AGXU HTTP/1.1" 200 -
ERROR passport.py:63 (pymysql.err.InternalError) (1054, "Unknown column 'password' in 'field list'")
[SQL: INSERT INTO ih_user_profile (create_time, update_time, name, password, mobile, real_name, id_card, avatar_url) VALUES (%(create_time)s, %(update_time)s, %(name)s, %(password)s, %(mobile)s, %(real_name)s, %(id_card)s, %(avatar_url)s)]
[parameters: {'create_time': datetime.datetime(2019, 6, 19, 16, 45, 12, 694056), 'update_time': datetime.datetime(2019, 6, 19, 16, 45, 12, 694056), 'name': 17603094068, 'password': 1234, 'mobile': 17603094068, 'real_name': None, 'id_card': None, 'avatar_url': None}]
(Background on this error at: http://sqlalche.me/e/2j85)
INFO _internal.py:122 127.0.0.1 - - [19/Jun/2019 16:45:12] "POST /api/v1.0/users HTTP/1.1" 200 -
INFO _internal.py:122  * Detected change in 'D:\\python_demo\\python\\09ihome\\ihome\\api_1_0\\passport.py', reloading
INFO _internal.py:122  * Restarting with stat
WARNING _internal.py:122  * Debugger is active!
INFO _internal.py:122  * Debugger PIN: 603-595-559
INFO _internal.py:122  * Running on http://127.0.0.1:5000/ (Press CTRL+C to quit)
INFO _internal.py:122  * Detected change in 'D:\\python_demo\\python\\09ihome\\ihome\\models.py', reloading
INFO _internal.py:122  * Restarting with stat
WARNING _internal.py:122  * Debugger is active!
INFO _internal.py:122  * Debugger PIN: 603-595-559
INFO _internal.py:122  * Running on http://127.0.0.1:5000/ (Press CTRL+C to quit)
INFO _internal.py:122 127.0.0.1 - - [19/Jun/2019 17:00:16] "POST /api/v1.0/users HTTP/1.1" 200 -
INFO _internal.py:122 127.0.0.1 - - [19/Jun/2019 17:00:28] "GET /api/v1.0/image_code/33 HTTP/1.1" 200 -
INFO _internal.py:122  * Detected change in 'D:\\python_demo\\python\\09ihome\\ihome\\constants.py', reloading
INFO _internal.py:122  * Restarting with stat
WARNING _internal.py:122  * Debugger is active!
INFO _internal.py:122  * Debugger PIN: 603-595-559
INFO _internal.py:122  * Running on http://127.0.0.1:5000/ (Press CTRL+C to quit)
INFO _internal.py:122 127.0.0.1 - - [19/Jun/2019 17:01:43] "GET /api/v1.0/sms_code/17603094068?image_code_id=33&image_code=F9AL HTTP/1.1" 200 -
INFO _internal.py:122 127.0.0.1 - - [19/Jun/2019 17:01:57] "POST /api/v1.0/users HTTP/1.1" 200 -
INFO _internal.py:122 127.0.0.1 - - [19/Jun/2019 17:02:10] "POST /api/v1.0/users HTTP/1.1" 200 -
INFO _internal.py:122 127.0.0.1 - - [19/Jun/2019 17:02:54] "GET /api/v1.0/sms_code/17603094068?image_code_id=33&image_code=F9AL HTTP/1.1" 200 -
INFO _internal.py:122 127.0.0.1 - - [19/Jun/2019 17:03:04] "GET /api/v1.0/image_code/33 HTTP/1.1" 200 -
INFO _internal.py:122  * Restarting with stat
WARNING _internal.py:122  * Debugger is active!
INFO _internal.py:122  * Debugger PIN: 603-595-559
INFO _internal.py:122  * Running on http://127.0.0.1:5000/ (Press CTRL+C to quit)
INFO _internal.py:122 127.0.0.1 - - [19/Jun/2019 17:04:50] "GET /api/v1.0/sms_code/17603094068?image_code_id=33&image_code=OZPU HTTP/1.1" 200 -
INFO _internal.py:122 127.0.0.1 - - [19/Jun/2019 17:04:59] "POST /api/v1.0/users HTTP/1.1" 500 -
INFO _internal.py:122  * Detected change in 'D:\\python_demo\\python\\09ihome\\ihome\\api_1_0\\passport.py', reloading
INFO _internal.py:122  * Restarting with stat
WARNING _internal.py:122  * Debugger is active!
INFO _internal.py:122  * Debugger PIN: 603-595-559
INFO _internal.py:122  * Running on http://127.0.0.1:5000/ (Press CTRL+C to quit)
INFO _internal.py:122 127.0.0.1 - - [19/Jun/2019 17:06:47] "POST /api/v1.0/users HTTP/1.1" 200 -
INFO _internal.py:122 127.0.0.1 - - [19/Jun/2019 17:06:55] "GET /api/v1.0/image_code/33 HTTP/1.1" 200 -
INFO _internal.py:122 127.0.0.1 - - [19/Jun/2019 17:07:46] "GET /api/v1.0/sms_code/17603094068?image_code_id=33&image_code=ZHRB HTTP/1.1" 200 -
INFO _internal.py:122  * Detected change in 'D:\\python_demo\\python\\09ihome\\ihome\\api_1_0\\passport.py', reloading
INFO _internal.py:122  * Restarting with stat
WARNING _internal.py:122  * Debugger is active!
INFO _internal.py:122  * Debugger PIN: 603-595-559
INFO _internal.py:122  * Running on http://127.0.0.1:5000/ (Press CTRL+C to quit)
INFO _internal.py:122  * Detected change in 'D:\\python_demo\\python\\09ihome\\config.py', reloading
INFO _internal.py:122  * Restarting with stat
WARNING _internal.py:122  * Debugger is active!
INFO _internal.py:122  * Debugger PIN: 603-595-559
INFO _internal.py:122  * Running on http://127.0.0.1:5000/ (Press CTRL+C to quit)
INFO _internal.py:122  * Detected change in 'D:\\python_demo\\python\\09ihome\\ihome\\__init__.py', reloading
INFO _internal.py:122  * Restarting with stat
WARNING _internal.py:122  * Debugger is active!
INFO _internal.py:122  * Debugger PIN: 603-595-559
INFO _internal.py:122  * Running on http://127.0.0.1:5000/ (Press CTRL+C to quit)
INFO _internal.py:122 127.0.0.1 - - [19/Jun/2019 17:19:17] "GET /api/v1.0/image_code/33 HTTP/1.1" 200 -
INFO _internal.py:122  * Restarting with stat
WARNING _internal.py:122  * Debugger is active!
INFO _internal.py:122  * Debugger PIN: 603-595-559
INFO _internal.py:122  * Running on http://127.0.0.1:5000/ (Press CTRL+C to quit)
INFO _internal.py:122 127.0.0.1 - - [19/Jun/2019 17:19:59] "GET /api/v1.0/sms_code/176030940681?image_code_id=33&image_code=TQPW HTTP/1.1" 404 -
INFO _internal.py:122 127.0.0.1 - - [19/Jun/2019 17:20:04] "GET /api/v1.0/sms_code/176030940681?image_code_id=33&image_code=TQPW HTTP/1.1" 404 -
INFO _internal.py:122 127.0.0.1 - - [19/Jun/2019 17:20:10] "GET /api/v1.0/sms_code/176030940681?image_code_id=33&image_code=TQPW HTTP/1.1" 404 -
INFO _internal.py:122 127.0.0.1 - - [19/Jun/2019 17:20:30] "GET /api/v1.0/sms_code/176030940681?image_code_id=33&image_code=TQPW HTTP/1.1" 404 -
INFO _internal.py:122 127.0.0.1 - - [19/Jun/2019 17:20:44] "GET /api/v1.0/sms_code/17603094061?image_code_id=33&image_code=TQPW HTTP/1.1" 200 -
INFO _internal.py:122 127.0.0.1 - - [19/Jun/2019 17:20:58] "POST /api/v1.0/users HTTP/1.1" 500 -
INFO _internal.py:122  * Detected change in 'D:\\python_demo\\python\\09ihome\\ihome\\__init__.py', reloading
INFO _internal.py:122  * Restarting with stat
WARNING _internal.py:122  * Debugger is active!
INFO _internal.py:122  * Debugger PIN: 603-595-559
INFO _internal.py:122  * Running on http://127.0.0.1:5000/ (Press CTRL+C to quit)
INFO _internal.py:122  * Detected change in 'D:\\python_demo\\python\\09ihome\\ihome\\__init__.py', reloading
INFO _internal.py:122  * Restarting with stat
WARNING _internal.py:122  * Debugger is active!
INFO _internal.py:122  * Debugger PIN: 603-595-559
INFO _internal.py:122  * Running on http://127.0.0.1:5000/ (Press CTRL+C to quit)
INFO _internal.py:122  * Detected change in 'D:\\python_demo\\python\\09ihome\\ihome\\api_1_0\\passport.py', reloading
INFO _internal.py:122  * Restarting with stat
WARNING _internal.py:122  * Debugger is active!
INFO _internal.py:122  * Debugger PIN: 603-595-559
INFO _internal.py:122  * Running on http://127.0.0.1:5000/ (Press CTRL+C to quit)
INFO _internal.py:122  * Detected change in 'D:\\python_demo\\python\\09ihome\\ihome\\api_1_0\\passport.py', reloading
INFO _internal.py:122  * Restarting with stat
INFO _internal.py:122  * Restarting with stat
WARNING _internal.py:122  * Debugger is active!
INFO _internal.py:122  * Debugger PIN: 603-595-559
INFO _internal.py:122  * Running on http://127.0.0.1:5000/ (Press CTRL+C to quit)
INFO _internal.py:122 127.0.0.1 - - [19/Jun/2019 17:31:38] "GET /api/v1.0/session HTTP/1.1" 500 -
INFO _internal.py:122 127.0.0.1 - - [19/Jun/2019 17:31:38] "GET /api/v1.0/session?__debugger__=yes&cmd=resource&f=style.css HTTP/1.1" 200 -
INFO _internal.py:122 127.0.0.1 - - [19/Jun/2019 17:31:38] "GET /api/v1.0/session?__debugger__=yes&cmd=resource&f=debugger.js HTTP/1.1" 200 -
INFO _internal.py:122 127.0.0.1 - - [19/Jun/2019 17:31:38] "GET /api/v1.0/session?__debugger__=yes&cmd=resource&f=jquery.js HTTP/1.1" 200 -
INFO _internal.py:122 127.0.0.1 - - [19/Jun/2019 17:31:39] "GET /api/v1.0/session?__debugger__=yes&cmd=resource&f=ubuntu.ttf HTTP/1.1" 200 -
INFO _internal.py:122 127.0.0.1 - - [19/Jun/2019 17:31:39] "GET /api/v1.0/session?__debugger__=yes&cmd=resource&f=console.png HTTP/1.1" 200 -
INFO _internal.py:122 127.0.0.1 - - [19/Jun/2019 17:31:39] "GET /api/v1.0/session?__debugger__=yes&cmd=resource&f=console.png HTTP/1.1" 200 -
INFO _internal.py:122  * Detected change in 'D:\\python_demo\\python\\09ihome\\ihome\\__init__.py', reloading
INFO _internal.py:122  * Restarting with stat
WARNING _internal.py:122  * Debugger is active!
INFO _internal.py:122  * Debugger PIN: 603-595-559
INFO _internal.py:122  * Running on http://127.0.0.1:5000/ (Press CTRL+C to quit)
ERROR users.py:8 err msg
WARNING users.py:9 warn msg
INFO users.py:10 info msg
DEBUG users.py:11 debug msg
INFO _internal.py:122 127.0.0.1 - - [19/Jun/2019 17:32:50] "GET /api/v1.0/ HTTP/1.1" 200 -
INFO _internal.py:122 127.0.0.1 - - [19/Jun/2019 17:32:50] "GET /api/v1.0/session HTTP/1.1" 500 -
INFO _internal.py:122 127.0.0.1 - - [19/Jun/2019 17:32:50] "GET /api/v1.0/session?__debugger__=yes&cmd=resource&f=style.css HTTP/1.1" 200 -
INFO _internal.py:122 127.0.0.1 - - [19/Jun/2019 17:32:50] "GET /api/v1.0/session?__debugger__=yes&cmd=resource&f=jquery.js HTTP/1.1" 200 -
INFO _internal.py:122 127.0.0.1 - - [19/Jun/2019 17:32:50] "GET /api/v1.0/session?__debugger__=yes&cmd=resource&f=debugger.js HTTP/1.1" 200 -
INFO _internal.py:122 127.0.0.1 - - [19/Jun/2019 17:32:50] "GET /api/v1.0/session?__debugger__=yes&cmd=resource&f=ubuntu.ttf HTTP/1.1" 200 -
INFO _internal.py:122 127.0.0.1 - - [19/Jun/2019 17:32:50] "GET /api/v1.0/session?__debugger__=yes&cmd=resource&f=console.png HTTP/1.1" 200 -
INFO _internal.py:122 127.0.0.1 - - [19/Jun/2019 17:38:30] "GET /session HTTP/1.1" 404 -
INFO _internal.py:122  * Restarting with stat
WARNING _internal.py:122  * Debugger is active!
INFO _internal.py:122  * Debugger PIN: 603-595-559
INFO _internal.py:122  * Running on http://127.0.0.1:5000/ (Press CTRL+C to quit)
INFO _internal.py:122 127.0.0.1 - - [19/Jun/2019 17:40:42] "GET /api/v1.0/image_code/33 HTTP/1.1" 200 -
INFO _internal.py:122 127.0.0.1 - - [19/Jun/2019 17:40:53] "GET /api/v1.0/session HTTP/1.1" 500 -
INFO _internal.py:122 127.0.0.1 - - [19/Jun/2019 17:40:53] "GET /api/v1.0/session?__debugger__=yes&cmd=resource&f=style.css HTTP/1.1" 200 -
INFO _internal.py:122 127.0.0.1 - - [19/Jun/2019 17:40:53] "GET /api/v1.0/session?__debugger__=yes&cmd=resource&f=jquery.js HTTP/1.1" 200 -
INFO _internal.py:122 127.0.0.1 - - [19/Jun/2019 17:40:53] "GET /api/v1.0/session?__debugger__=yes&cmd=resource&f=debugger.js HTTP/1.1" 200 -
INFO _internal.py:122 127.0.0.1 - - [19/Jun/2019 17:40:53] "GET /api/v1.0/session?__debugger__=yes&cmd=resource&f=ubuntu.ttf HTTP/1.1" 200 -
INFO _internal.py:122 127.0.0.1 - - [19/Jun/2019 17:40:53] "GET /api/v1.0/session?__debugger__=yes&cmd=resource&f=console.png HTTP/1.1" 200 -
INFO _internal.py:122  * Detected change in 'D:\\python_demo\\python\\09ihome\\ihome\\__init__.py', reloading
INFO _internal.py:122  * Restarting with stat
WARNING _internal.py:122  * Debugger is active!
INFO _internal.py:122  * Debugger PIN: 603-595-559
INFO _internal.py:122  * Running on http://127.0.0.1:5000/ (Press CTRL+C to quit)
